<?xml version="1.0"?>
<robot name="motor">
	
	<link name="world"/>

	<link name="base_link">
		<visual>
			<geometry>
				<box size="0.1 0.1 0.01"/>
				<origin xyz="0 0 0.01"/>
			</geometry>
		</visual>
		<collision>
			<geometry>
				<box size="0.1 0.1 0.01"/>
        <origin xyz="0 0 0.01"/>
			</geometry>
		</collision>
		<inertial>
			<mass value="0.1"/>
			<inertia ixx="1" ixy="0.0" ixz="0.0" iyy="0.1" iyz="0.0" izz="0.001"/>
		</inertial>
	</link>

<!--	<link name="rotor">
		<visual>
			<geometry>
				<cylinder length="0.055" radius="0.009"/>
			</geometry>
			<origin xyz="0 0 0" rpy="0 1.570796327 0"/>
		</visual>
		<collision>
      <geometry>
        <cylinder length="0.055" radius="0.009"/>
      </geometry>
      <origin xyz="0 0 0" rpy="0 1.570796327 0"/>
		</collision>
		<inertial>
      <mass value="0.1"/>
      <inertia ixx="1" ixy="0.0" ixz="0.0" iyy="0.1" iyz="0.0" izz="0.01"/>
    </inertial>
	</link> -->

  <link name="rotor">
    <visual>
      <geometry>
        <cylinder length="0.055" radius="0.009"/>
      </geometry>
      <origin xyz="0 0 0" rpy="0 0 0"/>
    </visual>
    <collision>
      <geometry>
        <cylinder length="0.055" radius="0.009"/>
      </geometry>
      <origin xyz="0 0 0" rpy="0 0 0"/>
    </collision>
    <inertial>
      <mass value="0.1"/>
      <inertia ixx="1" ixy="0.0" ixz="0.0" iyy="0.1" iyz="0.0" izz="0.01"/>
    </inertial>
	</link>

	<joint name="fixe_base" type="fixed">
		<parent link="world"/>
		<child link="base_link"/>
		<origin xyz="0 0 0.005"/>
	</joint>

<!--	<joint name="motor_axis" type="continuous">
		<parent link="base_link"/>
		<child link="rotor"/>
		<axis xyz="1 0 0"/>
		<origin xyz="0 0 0.1"/>
	</joint> -->

	<joint name="motor_axis" type="continuous">
    <parent link="base_link"/>
    <child link="rotor"/>
    <axis xyz="0 0 1"/>
    <origin xyz="0 0 0.1" rpy="0 1.570796327 0"/>
  </joint>

	<gazebo>
		<plugin name="motor_gazebo_plugins" filename="libgazebo_ros_motor.so">
			<motor_axis_joint_name>motor_axis</motor_axis_joint_name>
		</plugin>
	</gazebo>

</robot>
